<?xml version="1.0" ?>
<sdf version="1.6">
    
  <model name='turbine'>

    <link name="rotor">
      <pose>0 0 81.7 0 0 0</pose>

      <inertial>
        <mass>15</mass>
        <inertia>
          <ixx>1.0051</ixx>
          <iyy>1.0051</iyy>
          <izz>1.0090</izz>
          <ixy>0</ixy>
          <ixy>0</ixy>
          <ixz>0</ixz>
          <iyz>0</iyz>
        </inertia>
     </inertial>

     <!-- <collision name="collision">
        <pose>-4.5 0 0 0 1.5707 0</pose>
        <geometry>
          <cylinder>
            <radius>48</radius>
            <length>3</length>
          </cylinder>
        </geometry>
      </collision> -->

      <visual name="visual">
          <geometry>
            <mesh>
              <uri>model://turbine_rotor/meshes/rotor.dae</uri>
            </mesh>
          </geometry>
      </visual>
    </link>

    <model name='turbine_base'>

    <static>1</static>
    <pose frame=''>0 0 0 0 0 0</pose>

    <link name='mast'>

      <inertial>
        <mass>100000</mass>
        <inertia>
          <ixx>100000</ixx>
          <iyy>100000</iyy>
          <izz>100000</izz>
          <ixy>0</ixy>
          <ixy>0</ixy>
          <ixz>0</ixz>
          <iyz>0</iyz>
        </inertia>
      </inertial>

      <collision name='collision'>
        <pose>0 0 0  0 0 0</pose>
        <geometry>
          <mesh><uri>model://turbine_rotor/meshes/monopile.dae</uri></mesh>
        </geometry>
        <max_contacts>10</max_contacts>
      </collision>

      <visual name='visual'>
        <pose>0 0 0  0 0 0</pose>
        <geometry>
          <mesh><uri>model://turbine_rotor/meshes/monopile.dae</uri></mesh>
        </geometry>
      </visual>

      <self_collide>0</self_collide>
      <enable_wind>0</enable_wind>
      <kinematic>0</kinematic>
    </link>
    </model>


    <joint type="revolute" name="rotor_hinge">
      <pose>0 0 0 0 0 0</pose>
      <child>rotor</child>
      <parent>turbine_base::mast</parent>
      <axis>
        <xyz>1 0 0</xyz>
      </axis>
    </joint>

  -->

  </model>
</sdf>
